<?xml version="1.0" encoding="UTF-8"?>
<!-- Generated by org.testng.reporters.JUnitXMLReporter -->
<testsuite ignored="0" hostname="DESKTOP-T4MFR2V" failures="2" tests="11" name="Default test" time="0.235" errors="0" timestamp="22 Dec 2023 06:14:18 GMT">
  <testcase classname="TestNG.TestNG_Batch_Dec_12th.AssertionTopics" name="test1" time="0.034">
    <skipped/>
  </testcase> <!-- test1 -->
  <testcase classname="TestNG.TestNG_Batch_Dec_12th.AssertionTopics" name="test1" time="0.002">
    <skipped/>
  </testcase> <!-- test1 -->
  <testcase classname="TestNG.TestNG_Batch_Dec_12th.AssertionTopics" name="test1" time="0.013">
    <skipped/>
  </testcase> <!-- test1 -->
  <testcase classname="TestNG.TestNG_Batch_Dec_12th.AssertionTopics" name="test1" time="0.008">
    <failure type="java.lang.AssertionError" message="expected [Selenium] but found [Java]">
      <![CDATA[java.lang.AssertionError: expected [Selenium] but found [Java]
at org.testng.Assert.fail(Assert.java:96)
at org.testng.Assert.failNotEquals(Assert.java:776)
at org.testng.Assert.assertEqualsImpl(Assert.java:137)
at org.testng.Assert.assertEquals(Assert.java:118)
at org.testng.Assert.assertEquals(Assert.java:453)
at org.testng.Assert.assertEquals(Assert.java:463)
at TestNG.TestNG_Batch_Dec_12th.AssertionTopics.test1(AssertionTopics.java:27)
at java.base/jdk.internal.reflect.NativeMethodAccessorImpl.invoke0(Native Method)
at java.base/jdk.internal.reflect.NativeMethodAccessorImpl.invoke(NativeMethodAccessorImpl.java:77)
at java.base/jdk.internal.reflect.DelegatingMethodAccessorImpl.invoke(DelegatingMethodAccessorImpl.java:43)
at java.base/java.lang.reflect.Method.invoke(Method.java:568)
at org.testng.internal.MethodInvocationHelper.invokeMethod(MethodInvocationHelper.java:124)
at org.testng.internal.Invoker.invokeMethod(Invoker.java:583)
at org.testng.internal.Invoker.retryFailed(Invoker.java:839)
at org.testng.internal.Invoker.invokeTestMethods(Invoker.java:1010)
at org.testng.internal.TestMethodWorker.invokeTestMethods(TestMethodWorker.java:125)
at org.testng.internal.TestMethodWorker.run(TestMethodWorker.java:109)
at org.testng.TestRunner.privateRun(TestRunner.java:648)
at org.testng.TestRunner.run(TestRunner.java:505)
at org.testng.SuiteRunner.runTest(SuiteRunner.java:455)
at org.testng.SuiteRunner.runSequentially(SuiteRunner.java:450)
at org.testng.SuiteRunner.privateRun(SuiteRunner.java:415)
at org.testng.SuiteRunner.run(SuiteRunner.java:364)
at org.testng.SuiteRunnerWorker.runSuite(SuiteRunnerWorker.java:52)
at org.testng.SuiteRunnerWorker.run(SuiteRunnerWorker.java:84)
at org.testng.TestNG.runSuitesSequentially(TestNG.java:1208)
at org.testng.TestNG.runSuitesLocally(TestNG.java:1137)
at org.testng.TestNG.runSuites(TestNG.java:1049)
at org.testng.TestNG.run(TestNG.java:1017)
at org.testng.remote.AbstractRemoteTestNG.run(AbstractRemoteTestNG.java:115)
at org.testng.remote.RemoteTestNG.initAndRun(RemoteTestNG.java:251)
at org.testng.remote.RemoteTestNG.main(RemoteTestNG.java:77)
]]>
    </failure>
  </testcase> <!-- test1 -->
  <testcase classname="TestNG.TestNG_Batch_Dec_12th.AssertionTopics" name="test2" time="0.004"/>
  <testcase classname="TestNG.TestNG_Batch_Dec_12th.AssertionTopics" name="test3" time="0.007"/>
  <testcase classname="TestNG.TestNG_Batch_Dec_12th.AssertionTopics" name="test4" time="0.013">
    <skipped/>
  </testcase> <!-- test4 -->
  <testcase classname="TestNG.TestNG_Batch_Dec_12th.AssertionTopics" name="test4" time="0.001">
    <skipped/>
  </testcase> <!-- test4 -->
  <testcase classname="TestNG.TestNG_Batch_Dec_12th.AssertionTopics" name="test4" time="0.003">
    <skipped/>
  </testcase> <!-- test4 -->
  <testcase classname="TestNG.TestNG_Batch_Dec_12th.AssertionTopics" name="test4" time="0.003">
    <failure type="java.lang.AssertionError" message="The following asserts failed:
	expected [Selenium] but found [Java]">
      <![CDATA[java.lang.AssertionError: The following asserts failed:
expected [Selenium] but found [Java]
at org.testng.asserts.SoftAssert.assertAll(SoftAssert.java:43)
at TestNG.TestNG_Batch_Dec_12th.AssertionTopics.test4(AssertionTopics.java:55)
at java.base/jdk.internal.reflect.NativeMethodAccessorImpl.invoke0(Native Method)
at java.base/jdk.internal.reflect.NativeMethodAccessorImpl.invoke(NativeMethodAccessorImpl.java:77)
at java.base/jdk.internal.reflect.DelegatingMethodAccessorImpl.invoke(DelegatingMethodAccessorImpl.java:43)
at java.base/java.lang.reflect.Method.invoke(Method.java:568)
at org.testng.internal.MethodInvocationHelper.invokeMethod(MethodInvocationHelper.java:124)
at org.testng.internal.Invoker.invokeMethod(Invoker.java:583)
at org.testng.internal.Invoker.retryFailed(Invoker.java:839)
at org.testng.internal.Invoker.invokeTestMethods(Invoker.java:1010)
at org.testng.internal.TestMethodWorker.invokeTestMethods(TestMethodWorker.java:125)
at org.testng.internal.TestMethodWorker.run(TestMethodWorker.java:109)
at org.testng.TestRunner.privateRun(TestRunner.java:648)
at org.testng.TestRunner.run(TestRunner.java:505)
at org.testng.SuiteRunner.runTest(SuiteRunner.java:455)
at org.testng.SuiteRunner.runSequentially(SuiteRunner.java:450)
at org.testng.SuiteRunner.privateRun(SuiteRunner.java:415)
at org.testng.SuiteRunner.run(SuiteRunner.java:364)
at org.testng.SuiteRunnerWorker.runSuite(SuiteRunnerWorker.java:52)
at org.testng.SuiteRunnerWorker.run(SuiteRunnerWorker.java:84)
at org.testng.TestNG.runSuitesSequentially(TestNG.java:1208)
at org.testng.TestNG.runSuitesLocally(TestNG.java:1137)
at org.testng.TestNG.runSuites(TestNG.java:1049)
at org.testng.TestNG.run(TestNG.java:1017)
at org.testng.remote.AbstractRemoteTestNG.run(AbstractRemoteTestNG.java:115)
at org.testng.remote.RemoteTestNG.initAndRun(RemoteTestNG.java:251)
at org.testng.remote.RemoteTestNG.main(RemoteTestNG.java:77)
]]>
    </failure>
  </testcase> <!-- test4 -->
  <testcase classname="TestNG.TestNG_Batch_Dec_12th.AssertionTopics" name="verification" time="0.006"/>
</testsuite> <!-- Default test -->
